Workbook

Sheet Q4 Overview
B2: Team Axis | Social Media Calendar October 2026
B3: Mock plan for portfolio purposes. Not an official Team Axis document. Campaign names are original concepts. Dates, figures, venues and partner details are placeholders to confirm.
B5: Posting cadence
B6: Channel | C6: What goes out
B7: Instagram | C7: 3 posts a week (Mon, Wed, Fri). Reels for hosts and events, carousels for tips, statics for announcements.
B8: Facebook | C8: Cross-post from Instagram. Every post.
B9: Telegram | C9: Programme announcements and reminders only (see Also Post To column).
B12: Campaigns this month
B13: Campaign | C13: Dates
B14: Power Up Players S1 | C14: Teaser 2 Oct, launch 5 Oct. Step Quest continues to 28 Nov.
B15: Move It! Challenge | C15: Check-in 1 runs 12 to 23 Oct.
B16: Always-on | C16: Health tips, instructor features and community content.
B17: Coming next month | C17: Midweek Reset @ [MALL NAME] (18 to 20 Nov), Move It! Check-in 2 (10 to 20 Nov).
B19: Content pillar mix
B20: Pillar | C20: Target share | D20: Posts planned | E20: Actual share | F20: Variance
B21: Programme Promotion | C21: 0.4 | D21: =COUNTIF(Calendar!$E:$E,B21) -> 6 | E21: =IF($D$26=0,0,D21/$D$26) -> 0.46153846 | F21: =E21-C21 -> 0.061538462
B22: Community & Participants | C22: 0.15 | D22: =COUNTIF(Calendar!$E:$E,B22) -> 2 | E22: =IF($D$26=0,0,D22/$D$26) -> 0.15384615 | F22: =E22-C22 -> 0.0038461538
B23: Health Education | C23: 0.3 | D23: =COUNTIF(Calendar!$E:$E,B23) -> 4 | E23: =IF($D$26=0,0,D23/$D$26) -> 0.30769231 | F23: =E23-C23 -> 0.0076923077
B24: Instructors & Behind the Scenes | C24: 0.1 | D24: =COUNTIF(Calendar!$E:$E,B24) -> 1 | E24: =IF($D$26=0,0,D24/$D$26) -> 0.076923077 | F24: =E24-C24 -> -0.023076923
B25: Seasonal & Culture | C25: 0.05 | D25: =COUNTIF(Calendar!$E:$E,B25) -> 0 | E25: =IF($D$26=0,0,D25/$D$26) -> 0 | F25: =E25-C25 -> -0.05
B26: Total | C26: =SUM(C21:C25) -> 1 | D26: =SUM(D21:D25) -> 13
B27: Blue figures are editable targets. Launch month, so the mix leans promotional. Counts update from the Calendar tab.
B29: Posts by channel and week
B30: Channel | C30: Wk 1 (1 to 4) | D30: Wk 2 (5 to 11) | E30: Wk 3 (12 to 18) | F30: Wk 4 (19 to 25) | G30: Wk 5 (26 to 31) | H30: Total
B31: Instagram | C31: =COUNTIFS(Calendar!$B:$B,$B31,Calendar!$A:$A,">="&DATE(2026,10,1),Calendar!$A:$A,"<="&DATE(2026,10,4)) -> 1 | D31: =COUNTIFS(Calendar!$B:$B,$B31,Calendar!$A:$A,">="&DATE(2026,10,5),Calendar!$A:$A,"<="&DATE(2026,10,11)) -> 3 | E31: =COUNTIFS(Calendar!$B:$B,$B31,Calendar!$A:$A,">="&DATE(2026,10,12),Calendar!$A:$A,"<="&DATE(2026,10,18)) -> 3 | F31: =COUNTIFS(Calendar!$B:$B,$B31,Calendar!$A:$A,">="&DATE(2026,10,19),Calendar!$A:$A,"<="&DATE(2026,10,25)) -> 3 | G31: =COUNTIFS(Calendar!$B:$B,$B31,Calendar!$A:$A,">="&DATE(2026,10,26),Calendar!$A:$A,"<="&DATE(2026,10,31)) -> 3 | H31: =SUM(C31:G31) -> 13
B32: Total | C32: =SUM(C31:C31) -> 1 | D32: =SUM(D31:D31) -> 3 | E32: =SUM(E31:E31) -> 3 | F32: =SUM(F31:F31) -> 3 | G32: =SUM(G31:G31) -> 3 | H32: =SUM(H31:H31) -> 13
B35: Posts by status
B36: Status | C36: Posts
B37: Idea | C37: =COUNTIF(Calendar!$K:$K,$B37) -> 0
B38: Drafted | C38: =COUNTIF(Calendar!$K:$K,$B38) -> 0
B39: In Design | C39: =COUNTIF(Calendar!$K:$K,$B39) -> 0
B40: Awaiting Approval | C40: =COUNTIF(Calendar!$K:$K,$B40) -> 6
B41: Scheduled | C41: =COUNTIF(Calendar!$K:$K,$B41) -> 7
B42: Published | C42: =COUNTIF(Calendar!$K:$K,$B42) -> 0
B43: Total | C43: =SUM(C37:C42) -> 13
B46: Key dates this month (Singapore)
B47: Occasion | C47: Date | D47: Tie-in
B48: Children's Day (primary schools) | C48: 2 Oct | D48: No post planned
B49: World Mental Health Day | C49: 10 Oct | D49: 14 Oct reel
B50: Pink October | C50: All month | D50: 19 Oct carousel
...

Sheet Month View
A1: October 2026
A2: Mon | B2: Tue | C2: Wed | D2: Thu | E2: Fri | F2: Sat | G2: Sun
D3: 1 | E3: 2 | F3: 3 | G3: 4
E4: ★ Children's Day IG · Reel Teaser: Something New Is Loading
A5: 5 | B5: 6 | C5: 7 | D5: 8 | E5: 9 | F5: 10 | G5: 11
A6: IG · Carousel Season 1 Launch: Step Quest Starts Now | C6: IG · Reel How to Earn XP | E6: IG · Reel Let's Talk About Power Up Players, Part 1 | F6: ★ World Mental Health Day
A7: 12 | B7: 13 | C7: 14 | D7: 15 | E7: 16 | F7: 17 | G7: 18
A8: IG · Static Check-in 1 Opens Today | C8: IG · Reel 5 Desk Resets in 30 Seconds | E8: IG · Reel Let's Talk About Power Up Players, Part 2
A9: 19 | B9: 20 | C9: 21 | D9: 22 | E9: 23 | F9: 24 | G9: 25
A10: IG · Carousel Pink October: Know What's Normal for You | C10: IG · Reel Quest Photos From Week 2 | E10: IG · Reel Meet Your Instructor: [NAME]
A11: 26 | B11: 27 | C11: 28 | D11: 29 | E11: 30 | F11: 31
A12: IG · Carousel Healthier Hawker Swaps | C12: IG · Reel Know the Signs of Stroke | D12: ★ World Stroke Day | E12: IG · Static Halfway Leaderboard
A14: Key | B14: Instagram | C14: ★ Key date
A15: Full captions, hooks and notes are in the Calendar tab.

Sheet Calendar
A1: Date | B1: Channel | C1: Format | D1: Campaign | E1: Content Pillar | F1: Post Title | G1: Caption | H1: Reel Hook / On-screen Text | I1: Key Date Tie-in | J1: Also Post To | K1: Status | L1: Notes
A2: 46297 | B2: Instagram | C2: Reel | D2: Power Up Players S1 | E2: Programme Promotion | F2: Teaser: Something New Is Loading | G2: Something new is loading 🎮 Grab a colleague, charge up your step counter and get ready. A brand new way to stay active together drops this Monday. Any guesses? Drop them below 👇 #TeamAxisSG #ComingSoon #WorkplaceWellness | H2: Loading... Player 2 needed. | J2: Facebook, Telegram | K2: Scheduled | L2: Pixel-art style teaser, 10 to 15 sec.
A3: 46300 | B3: Instagram | C3: Carousel | D3: Power Up Players S1 | E3: Programme Promotion | F3: Season 1 Launch: Step Quest Starts Now | G3: Player 1, ready? Power Up Players Season 1 is officially live! 🏆 Step Quest runs from 5 Oct to 28 Nov. Bring a colleague along on three healthy quests, snap a photo and submit it to earn trophies. 🏃 Move together 🥗 Fuel up with a shared meal 💌 Recharge with an encouraging note Collect five trophies to unlock your first reward. Tag the teammate you're bringing along 👇 #PowerUpPlayers #TeamAxisSG #WorkplaceWellness | J3: Facebook, Telegram | K3: Scheduled | L3: Design ready: mock post 01 (Season launch).
A4: 46302 | B4: Instagram | C4: Reel | D4: Power Up Players S1 | E4: Programme Promotion | F4: How to Earn XP | G4: Three ways to rack up XP this season, explained in under a minute ⏱️ Stay till the end for the bonus quest most players miss. Which one are you starting with? Drop a 1, 2 or 3 below 👇 #PowerUpPlayers #LevelUpYourHealth #TeamAxisSG | H4: You're leaving XP on the table. Here's how to fix that. | J4: Facebook, Telegram | K4: Scheduled | L4: Cover: mock post 02 (yellow duotone).
A5: 46304 | B5: Instagram | C5: Reel | D5: Power Up Players S1 | E5: Programme Promotion | F5: Let's Talk About Power Up Players, Part 1 | G5: New here? Our host sits down with [GUEST NAME] to break down what Power Up Players is, who can join and why your whole team should sign up together 🙌 Part 2 drops next Friday. Save this so you don't miss it 🔔 #PowerUpPlayers #WorkplaceWellness #TeamAxisSG | H5: So what actually is Power Up Players? | J5: Facebook, Telegram | K5: Scheduled | L5: Cover: mock post 03 (blue duotone).
A6: 46307 | B6: Instagram | C6: Static | D6: Move It! Challenge | E6: Programme Promotion | F6: Check-in 1 Opens Today | G6: Check-in 1 of the Move It! Challenge 2026 opens today 📋 Drop by any check-in station from 12 to 23 Oct, track your progress and start earning vouchers. First-timers get a free healthy snack pack (while stocks last) 🥜 Search 'Move It' on [APP NAME] to sign up. #MoveItChallenge #TeamAxisSG #HealthyLiving | J6: Facebook, Telegram | K6: Scheduled | L6: Adapt mock post 05 layout for Check-in 1.
A7: 46309 | B7: Instagram | C7: Reel | D7: Always-on | E7: Health Education | F7: 5 Desk Resets in 30 Seconds | G7: World Mental Health Day was last Saturday, but looking after your mind is an everyday thing 💙 Here are five quick resets you can do between meetings, no gym required. Save this for your next 3pm slump and send it to a colleague who needs it. #WorldMentalHealthDay #MindMatters #TeamAxisSG | H7: Your 3pm slump fix is here. | I7: World Mental Health Day (10 Oct) | J7: Facebook | K7: Scheduled
A8: 46311 | B8: Instagram | C8: Reel | D8: Power Up Players S1 | E8: Programme Promotion | F8: Let's Talk About Power Up Players, Part 2 | G8: Part 2 is here 🎙️ Our host and [GUEST NAME] cover who can join, how trophies turn into rewards and the one tip that helps teams stay consistent. Missed Part 1? It's on our profile. #PowerUpPlayers #TeamAxisSG | H8: Who can join, and what can you win? | J8: Facebook, Telegram | K8: Scheduled | L8: Blue duotone cover, 'Part 2'.
A9: 46314 | B9: Instagram | C9: Carousel | D9: Always-on | E9: Health Education | F9: Pink October: Know What's Normal for You | G9: It's Pink October 🎀 Breast cancer awareness is about knowing what's normal for your body and not putting off screenings. Swipe for simple reminders, and visit HealthHub for screening information. Share this with someone you love. #PinkOctober #BreastCancerAwareness #TeamAxisSG | I9: Pink October | J9: Facebook | K9: Awaiting Approval | L9: Check all health content against HPB and HealthHub guidance before posting.
A10: 46316 | B10: Instagram | C10: Reel | D10: Power Up Players S1 | E10: Community & Participants | F10: Quest Photos From Week 2 | G10: You all brought the energy this week 🔥 Here are some of our favourite Step Quest submissions so far, from lunchtime walks to shared salads. Keep them coming, every photo counts towards your trophies! #PowerUpPlayers #TeamAxisSG #QuestComplete | H10: POV: your team actually showed up. | J10: Facebook, Telegram | K10: Awaiting Approval | L10: Feature only submissions with photo consent.
A11: 46318 | B11: Instagram | C11: Reel | D11: Always-on | E11: Instructors & Behind the Scenes | F11: Meet Your Instructor: [NAME] | G11: Meet [NAME], one of the friendly faces leading our [CLASS TYPE] sessions 👋 [NAME] has been coaching for [X] years and believes [ONE-LINE PHILOSOPHY]. Catch them at our next session and say hi! #MeetYourInstructor #TeamAxisSG #SGFitness | H11: Meet the person behind your favourite class. | J11: Facebook | K11: Awaiting Approval | L11: Instructor to approve final cut.
A12: 46321 | B12: Instagram | C12: Carousel | D12: Always-on | E12: Health Education | F12: Healthier Hawker Swaps | G12: Hawker food is part of who we are 🍜 and eating well doesn't mean giving it up. Swipe for five easy swaps that cut down on sugar, salt and oil without losing the flavour. Which swap are you trying this week? #HealthierChoice #HawkerFood #TeamAxisSG | J12: Facebook | K12: Awaiting Approval | L12: Check swaps against HPB healthier choice guidance.
A13: 46323 | B13: Instagram | C13: Reel | D13: Always-on | E13: Health Education | F13: Know the Signs of Stroke | G13: Tomorrow is World Stroke Day. Knowing the warning signs can help someone get treatment faster. Watch, save and share, and if you notice these signs, call 995 immediately. #WorldStrokeDay #KnowTheSigns #TeamAxisSG | H13: Every minute counts. Would you know what to look for? | I13: World Stroke Day (29 Oct) | J13: Facebook | K13: Awaiting Approval | L13: Use the official warning-signs acronym from a recognised Singapore health source. Verify before posting.
A14: 46325 | B14: Instagram | C14: Static | D14: Power Up Players S1 | E14: Community & Participants | F14: Halfway Leaderboard | G14: The halfway leaderboard is in 🏆 Congratulations to [TEAM 1], [TEAM 2] and [TEAM 3] for leading the pack. Four weeks left to climb, so grab your colleagues and keep questing! #PowerUpPlayers #Leaderboard #TeamAxisSG | J14: Facebook, Telegram | K14: Awaiting Approval | L14: Confirm standings on the day.

Sheet Campaign Briefs
A1: Field | B1: Power Up Players S1 | C1: Move It! Challenge
A2: Dates | B2: 5 Oct to 28 Nov 2026. Winners announced 11 Dec. | C2: Check-in 1: 12 to 23 Oct (this month). Check-ins 2 and 3 follow in Nov and Dec.
A3: Objective | B3: Drive sign-ups and sustained weekly participation in a team-based workplace wellness programme. | C3: Increase check-in completion across all three cycles and bring in first-time participants.
A4: Target audience | B4: Office workers and their colleagues. | C4: Adults building a regular health habit, including first-timers and returning participants.
A5: Key message | B5: Staying healthy is easier with a teammate. Bring a colleague, complete quests, level up together. | C5: It's not too late to join. Every check-in counts, and there are rewards along the way.
A6: How it works | B6: Pairs complete three quest types (Move Together, Fuel Up, Recharge), submit a photo per quest and earn trophies. Five trophies unlock a reward. Top teams win at season end. | C6: Participants visit a check-in station during each cycle to track progress. Vouchers are earned for completed check-ins. First-timers receive a free healthy snack pack while stocks last.
A7: Channels | B7: Instagram (launch, host reels, leaderboard, countdown, winners), Facebook, Telegram reminders. | C7: Instagram statics for each cycle opening and closing, Facebook, Telegram reminders.
A8: Hero assets | B8: Mock posts 01 (launch), 02 and 03 (reel covers). Pixel-art style with blue and yellow duotone reels. Mock post 04 (countdown) is for November. | C8: Adapt mock post 05 layout for Check-in 1. Torn-paper style with red, blue and green accents.
A9: Metrics to track | B9: Sign-ups, weekly quest submissions, reel views and saves, profile visits, link-in-bio clicks. | C9: Check-in completions per cycle, first-time sign-ups, app searches for 'Move It', reminder post reach.
A10: Call to action | B10: Sign up and tag the colleague you're bringing along. | C10: Search 'Move It' on [APP NAME] to join.
A11: Notes | B11: Only feature participant photos with consent. Season 2 teased for 2027. | C11: Voucher values and station locations to confirm.
